<?xml version="1.0"?>
<robot xmlns:xacro="http://www.ros.org/wiki/xacro">

    <material name="white">
        <color rgba="1 1 1 1" />
    </material>

    <material name="blue">
        <color rgba="0 0 1 1" />
    </material>

    <material name="black">
        <color rgba="0 0 0 1" />
    </material>

    <material name="cyan">
        <color rgba="0 1 1 1" />
    </material>

    <material name="green">
        <color rgba="0 1 0 1" />
    </material>

    <xacro:property name="PI" value="3.1415926" />
    <xacro:property name="velocity" value="2" />
    <xacro:property name="base_size" value="0.2 0.2 2" />
    <xacro:property name="arm_base" value="0.2 0.1 0.1" />
    <xacro:property name="rotate_base" value="0.1 0.1 0.1" />
    <xacro:property name="lower_arm" value="0.4 0.1 0.1" />
    <xacro:property name="mid_arm" value="0.3 0.08 0.08" />
    <xacro:property name="upper_arm" value="0.2 0.06 0.06" />
    <xacro:property name="wrist1" value="0.04 0.04 0.04" />
    <xacro:property name="wrist2" value="0.02 0.02 0.02" />
    <xacro:property name="wrist3" value="0.05 0.01 0.01" />
    <xacro:property name="camera" value="0.02 0.02 0.02" /> 

    <xacro:property name="base_mass" value="1000" />
    <xacro:property name="rotate_mass" value="40" />
    <xacro:property name="lower_mass" value="10" />
    <xacro:property name="mid_mass" value="8" />
    <xacro:property name="upper_mass" value="6" />
    <xacro:property name="wrist1_mass" value="5" />
    <xacro:property name="wrist2_mass" value="4" />
    <xacro:property name="wrist3_mass" value="3" />
    <xacro:property name="camera_mass" value="0.0" />
    
    <xacro:macro name="box_inertial_matrix" params="mass length width height *origin">
        <inertial>
            <mass value="${mass}" />
            <inertia ixx="${0.0833333*mass*(width*width+height*height)}" ixy="0" ixz="0"
                    iyy="${0.0833333*mass*(length*length+height*height)}" iyz="0"
                    izz="${0.0833333*mass*(width*width+height*height)}" />
        </inertial>
        <xacro:insert_block name="origin" />
    </xacro:macro>

    <xacro:macro name="arm2">
        <link name="base">
            <visual>
                <geometry>
                    <box size="${base_size}" />
                </geometry>
                <origin rpy="0 0 0" xyz="0 0 1" />
                <material name="black" />
            </visual>
            <collision>
                <geometry>
                    <box size="0.001 0.001 0.001" />
                </geometry>
                <origin rpy="0 0 0" xyz="0 0 1" />
            </collision>
            <xacro:box_inertial_matrix mass="${base_mass}" length="0.2" width="0.2" height="1">
                <origin rpy="0 0 0" xyz="0 0 1" />
            </xacro:box_inertial_matrix>
        </link>

        <link name="arm_base">
            <visual>
                <geometry>
                    <box size="${arm_base}" />
                </geometry>
                <origin rpy="0 0 0" xyz="-0.1 0 0" />
                <material name="white" />
            </visual>
            <collision>
                <geometry>
                    <box size="0.0 0.0 0.0" />
                </geometry>
                <origin rpy="0 0 0" xyz="-0.1 0 0" />
            </collision>
            <xacro:box_inertial_matrix mass="0.1" length="0.2" width="0.1" height="0.1">
                <origin rpy="0 0 0" xyz="-0.1 0 0" />
            </xacro:box_inertial_matrix>
        </link>

        <joint name="base_to_arm_base" type="fixed">
            <parent link="base" />
            <child link="arm_base" />
            <origin rpy="0 0 0" xyz="-0.1 0 1.2" />
        </joint>

        <link name="camera_link">
            <visual>
                <geometry>
                    <box size="${camera}" />
                </geometry>
                <material name="white" />
                <origin rpy="0 0 0" xyz="0 0 0" />
            </visual>
            <collision>
                <geometry>
                    <box size="${camera}" />
                </geometry>
                <origin rpy="0 0 0" xyz="0 0 0" />
            </collision>
            <xacro:box_inertial_matrix mass="${camera_mass}" length="0.001" width="0.001" height="0.001">
                <origin rpy="0 0 0" xyz="0 0 0" />
            </xacro:box_inertial_matrix>
        </link>

        <joint name="camera_joint" type="fixed">
            <parent link="base" />
            <child link="camera_link" />
            <origin rpy="0 1.57075 1.57075" xyz="0 0.7 1.8" />
            <axis xyz="0 0 1" />
        </joint>

        <link name="camera_link2">
            <visual>
                <geometry>
                    <box size="${camera}" />
                </geometry>
                <material name="white" />
                <origin rpy="0 0 0" xyz="0 0 0" />
            </visual>
            <collision>
                <geometry>
                    <box size="${camera}" />
                </geometry>
                <origin rpy="0 0 0" xyz="0 0 0" />
            </collision>
            <xacro:box_inertial_matrix mass="${camera_mass}" length="0.001" width="0.001" height="0.001">
                <origin rpy="0 0 0" xyz="0 0 0" />
            </xacro:box_inertial_matrix>
        </link>

        <joint name="camera2_joint" type="fixed">
            <parent link="base" />
            <child link="camera_link2" />
            <origin rpy="0 0 -1.57075" xyz="-1.56 0.5 0.25" />
            <axis xyz="0 0 1" />
        </joint>

        <link name="rotate_base">
            <visual>
                <geometry>
                    <box size="${rotate_base}" />
                </geometry>
                <material name="blue" />
                <origin rpy="0 0 0" xyz="-0.05 0 0" />
            </visual>
            <collision>
                <geometry>
                    <box size="${rotate_base}" />
                </geometry>
                <origin rpy="0 0 0" xyz="-0.05 0 0" />
            </collision>
            <xacro:box_inertial_matrix mass="${rotate_mass}" length="0.1" width="0.1" height="0.1">
                <origin rpy="0 0 0" xyz="-0.05 0 0" />
            </xacro:box_inertial_matrix>
        </link>

        <joint name="rotation_joint" type="revolute">
            <parent link="arm_base" />
            <child link="rotate_base" />
            <limit effort="150" lower="${-2*PI}" upper="${2*PI}" velocity="${velocity}" />
            <origin rpy="0 0 0" xyz="-0.2 0 0" />
            <dynamics damping="0.1" friction="0.1" />
        </joint>

        <link name="lower_arm">
            <visual>
                <geometry>
                    <box size="${lower_arm}" />
                </geometry>
                <material name="cyan" />
                <origin rpy="0 0 0" xyz="-0.15 -0.05 0" />
            </visual>
            <collision>
                <geometry>
                    <box size="${lower_arm}" />
                </geometry>
                <origin rpy="0 0 0" xyz="-0.15 -0.05 0" />
            </collision>
            <xacro:box_inertial_matrix mass="${lower_mass}" length="0.4" width="0.1" height="0.1">
                <origin rpy="0 0 0" xyz="-0.15 -0.05 0" />
            </xacro:box_inertial_matrix>
        </link>

        <joint name="lower_joint" type="revolute"> 
            <parent link="rotate_base" />
            <child link="lower_arm" />
            <origin rpy="0 0 0" xyz="-0.05 -0.05 0" />
            <axis xyz="0 1 0" />
            <limit effort="150" lower="${-0.5*PI}" upper="${0.5*PI}" velocity="${velocity}" />
            <dynamics damping="0.1" friction="0.1" />
        </joint>

        <link name="mid_arm">
            <visual>
                <geometry>
                    <box size="${mid_arm}" />
                </geometry>
                <origin rpy="0 0 0" xyz="-0.1 0.04 0" />
                <material name="blue" />
            </visual>
            <collision>
                <geometry>
                    <box size="${mid_arm}" />
                </geometry>
                <origin rpy="0 0 0" xyz="-0.1 0.04 0" />
            </collision>
            <xacro:box_inertial_matrix mass="${mid_mass}" length="0.3" width="0.08" height="0.08">
                <origin rpy="0 0 0" xyz="-0.1 0.04 0" />
            </xacro:box_inertial_matrix>
        </link>

        <joint name="mid_joint" type="revolute">
            <parent link="lower_arm" />
            <child link="mid_arm" />
            <origin rpy="0 0 0" xyz="-0.35 0 0" />
            <limit effort="150" lower="${-0.5*PI}" upper="${0.5*PI}" velocity="${velocity}" />
            <axis xyz="0 1 0" />
            <dynamics damping="0.1" friction="0.1" />
        </joint>

        <link name="upper_arm">
            <visual>
                <geometry>
                    <box size="${upper_arm}" />
                </geometry>
                <material name="cyan" />
                <origin rpy="0 0 0" xyz="-0.05 -0.03 0" />
            </visual>
            <collision>
                <geometry>
                    <box size="${upper_arm}" />
                </geometry>
                <origin rpy="0 0 0" xyz="-0.05 -0.03 0" />
            </collision>
            <xacro:box_inertial_matrix mass="${upper_mass}" length="0.2" width="0.06" height="0.06">
                <origin rpy="0 0 0" xyz="-0.05 -0.03 0" />
            </xacro:box_inertial_matrix>
        </link>

        <joint name="upper_joint" type="revolute">
            <parent link="mid_arm" />
            <child link="upper_arm" />
            <origin rpy="0 0 0" xyz="-0.25 0 0" />
            <axis xyz="0 1 0" />
            <limit effort="150" lower="${-0.5*PI}" upper="${0.5*PI}" velocity="${velocity}" />
            <dynamics damping="0.1" friction="0.1" />
        </joint>

        <link name="wrist1">
            <visual>
                <geometry>
                    <box size="${wrist1}" />
                </geometry>
                <origin rpy="0 0 0" xyz="-0.02 0 0" />
                <material name="blue" />
            </visual>
            <collision>
                <geometry>
                    <box size="${wrist1}" />
                </geometry>
                <origin rpy="0 0 0" xyz="-0.02 0 0" />
            </collision>
            <xacro:box_inertial_matrix mass="${wrist1_mass}" length="0.04" width="0.04" height="0.04">
                <origin rpy="0 0 0" xyz="-0.02 0 0" />
            </xacro:box_inertial_matrix>
        </link>

        <joint name="wrist1_joint" type="revolute">
            <parent link="upper_arm" />
            <child link="wrist1" />
            <origin rpy="0 0 0" xyz="-0.15 -0.03 0" />
            <limit effort="150" lower="${-0.5*PI}" upper="${0.5*PI}" velocity="${velocity}" />
            <dynamics damping="0.1" friction="0.1" />
        </joint>

        <link name="wrist2">
            <visual>
                <geometry>
                    <box size="${wrist2}" />
                </geometry>
                <material name="white" />
                <origin rpy="0 0 0" xyz="0 -0.01 0" />
            </visual>
            <collision>
                <geometry>
                    <box size="${wrist2}" />
                </geometry>
                <origin rpy="0 0 0" xyz="0 -0.01 0" />
            </collision>
            <xacro:box_inertial_matrix mass="${wrist2_mass}" length="0.02" width="0.02" height="0.02">
                <origin rpy="0 0 0" xyz="0 -0.01 0" />
            </xacro:box_inertial_matrix>
        </link>

        <joint name="wrist2_joint" type="revolute">
            <parent link="wrist1" />
            <child link="wrist2" />
            <origin rpy="0 0 0" xyz="-0.02 -0.02 0" />
            <limit effort="150" lower="${-0.5*PI}" upper="${0.5*PI}" velocity="${velocity}" />
            <dynamics damping="0.1" friction="0.1" />
            <axis xyz="0 1 0" />
        </joint>

        <link name="wrist3">
            <visual>
                <geometry>
                    <box size="${wrist3}" />
                </geometry>
                <material name="black" />
                <origin rpy="0 0 0" xyz="-0.025 0 0" />
            </visual>
            <collision>
                <geometry>
                    <box size="${wrist3}" />
                </geometry>
                <origin rpy="0 0 0" xyz="-0.025 0 0" />
            </collision>
            <xacro:box_inertial_matrix mass="${wrist3_mass}" length="0.05" width="0.01" height="0.01">
                <origin rpy="0 0 0" xyz="-0.025 0 0" />
            </xacro:box_inertial_matrix>
        </link>

        <joint name="wrist3_joint" type="revolute">
            <parent link="wrist2" />
            <child link="wrist3" />
            <origin rpy="0 0 0" xyz="-0.01 -0.01 0" />
            <limit effort="150" lower="${-0.5*PI}" upper="${0.5*PI}" velocity="${velocity}" />
            <dynamics damping="0.1" friction="0.1" />
        </joint>

    </xacro:macro>

    <xacro:include filename="$(find rrbot)/urdf/arm2.gazebo" />
    
</robot>