<?xml version="1.0"?>
    <robot name="arm">

    <material name="white">
        <color rgba="1 1 1 1" />
    </material>

    <material name="blue">
        <color rgba="0 0 1 1" />
    </material>

    <material name="black">
        <color rgba="0 0 0 1" />
    </material>

    <material name="yellow">
        <color rgba="0 1 1 1" />
    </material>

    <material name="green">
        <color rgba="0 1 0 1" />
    </material>

    <link name="base">
        <visual>
            <geometry>
                <box size="2 2 1" />
             </geometry>
            <material name="black" />
        </visual>
    </link>

    <link name="arm_base">
        <visual>
            <geometry>
                 <cylinder length="0.01" radius="0.2" />
            </geometry>
            <origin rpy="0 0 0" xyz="0 0 0.005" />
            <material name="green" />
        </visual>
    </link>

     <link name="lower_arm0">
        <visual>
            <geometry>
                <box size="0.4 0.4 0.4" />
            </geometry>
            <origin rpy="0 0 0" xyz="0 0 0.2" />
            <material name="white" />
        </visual>
    </link>

    <link name="lower_arm">
        <visual>
            <geometry>
                <box size="0.4 0.4 2" />
            </geometry>
            <origin rpy="0 0 0" xyz="-0.2 0 0.8" />
            <material name="blue" />
        </visual>
    </link>

    <link name="mid_arm">
        <visual>    
            <geometry>  
                <box size="0.4 0.4 1.5" />
            </geometry>
            <origin rpy="0 0 0" xyz="0.2 0 0.55" />
            <material name="white" />
        </visual>
    </link>

    <link name="upper_arm">
        <visual>
            <geometry>
                <box size="0.4 0.4 1" />
            </geometry>
            <origin rpy="0 0 0" xyz="-0.2 0 0.3" />
            <material name="blue" />
        </visual>
    </link>

    <link name="gripper_base">  
        <visual>
            <geometry>
                <box size="0.4 0.4 0.4" />
            </geometry>
            <material name="white" />
        </visual>
    </link>

    <link name="left_gripper0">
        <visual>
            <geometry>
                <box size="0.4 0.05 0.2" />
            </geometry>
            <origin xyz="-0.2 -0.1 0" rpy="0 0 0.523598775" />
            <material name="green" />
        </visual>
    </link>

    <link name="right_gripper0">
        <visual>
            <geometry>
                <box size="0.4 0.05 0.2" />
            </geometry>
            <origin xyz="-0.2 0.1 0" rpy="0 0 -0.523598775" />
            <material name="green" />
        </visual>
    </link>

    <link name="left_gripper1">
        <visual>
            <geometry>
                <box size="0.2 0.05 0.2" />
            </geometry>
            <origin xyz="-0.1 0 0" />
        </visual>
    </link>

    <link name="right_gripper1">
        <visual>
            <geometry>
                <box size="0.2 0.05 0.2" />
            </geometry>
            <origin xyz="-0.1 0 0" />
        </visual>
    </link>

    <joint name="base_to_arm_base" type="continuous">
        <parent link="base" />
        <child link="arm_base" />
        <origin rpy="0 0 0" xyz="0 0 0.5" />
        <axis xyz="0 0 1" />
    </joint>

    <joint name="arm_base_to_lower_arm0" type="fixed">
        <parent link="arm_base" />
        <child link="lower_arm0" />
        <origin rpy="0 0 0" xyz="0 0 0.005" />
    </joint>

    <joint name="lower_arm0_to_lower_arm" type="revolute">
        <parent link="lower_arm0" />
        <child link="lower_arm" />
        <origin rpy="0 0 0" xyz="-0.2 0 0.2" />
        <limit effort="1000" lower="-1.57075" upper="1.57075" velocity="0.5" />
    </joint>

    <joint name="lower_arm_to_mid_arm" type="revolute">
        <parent link="lower_arm" />
        <child link="mid_arm" />
        <origin rpy="0 0 0" xyz="0 0 1.6" />
        <limit effort="800" lower="-1.57075" upper="1.57075" velocity="0.5" />
    </joint>

    <joint name="mid_arm_to_upper_arm" type="revolute">
        <parent link="mid_arm" />
        <child link="upper_arm" />
        <origin rpy="0 0 0" xyz="0 0 1.1" />
        <limit effort="600" lower="-1.57075" upper="1.57075" velocity="0.5" />
    </joint>

    <joint name="upper_arm_to_gripper_base" type="revolute">
        <parent link="upper_arm" />
        <child link="gripper_base" />
        <origin rpy="0 0 0" xyz="-0.2 0 1" />
        <axis xyz="0 0 1" />
        <limit effort="500" lower="0" upper="3.1415" velocity="0.5" />
    </joint>

    <joint name="gripper_base_to_left_gripper0" type="revolute">
        <parent link="gripper_base" />
        <child link="left_gripper0" />
        <origin rpy="0 0 0" xyz="-0.2 -0 0" />
        <axis xyz="0 0 1" />
        <limit effort="1500" lower="0" upper="1" velocity="0.5" />
    </joint>

     <joint name="gripper_base_to_right_gripper0" type="revolute">
        <parent link="gripper_base" />
        <child link="right_gripper0" />
        <origin rpy="0 0 0" xyz="-0.2 0 0" />
        <axis xyz="0 0 1" />
        <limit effort="1500" lower="-1" upper="0" velocity="0.5" />
    </joint>

    <joint name="left_gripper_part2" type="revolute">
        <parent link="left_gripper0" />
        <child link="left_gripper1" />
        <origin rpy="0 0 0" xyz="-0.346410161 -0.2 0" />
        <axis xyz="0 0 1" />
        <limit effort="1000" lower="-1.57075" upper="1.57075" velocity="0.5" />
    </joint>

    <joint name="right_gripper_part2" type="revolute">
        <parent link="right_gripper0" />
        <child link="right_gripper1" />
        <origin rpy="0 0 0" xyz="-0.346410161 0.2 0" />
        <axis xyz="0 0 1" />
        <limit effort="1000" lower="1.57075" upper="-1.57075" velocity="0.5" />
    </joint>

    </robot> 