<?xml version="1.0"?>
<robot name="robot0">

  <material name="white">
    <color rgba="1 1 1 1" />
  </material>

  <material name="blue">
    <color rgba="0 0 1 1" />
  </material>

  <material name="black">
    <color rgba="0 0 0 1" />
  </material>

  <material name="yellow">
    <color rgba="1 1 0 1" />
  </material>

  <link name="base_link">
    <visual>
      <geometry>
        <cylinder length="0.6" radius="0.2" />
      </geometry>
      <material name="blue" />
    </visual>
    <collision>
      <geometry>
        <cylinder length="0.6" radius="0.2" />
      </geometry>
    </collision>
    <inertial>
      <mass value="5" />
      <inertia ixx="0.2" ixy="0" ixz="0"
                iyy="0.2" iyz="0"
                izz="0.01" />
    </inertial>
  </link>

  <link name="right_leg">
    <visual>
      <geometry>
        <box size="0.6 0.1 0.2" />
      </geometry>
       <origin rpy="0 1.57075 0" xyz="0 0 -0.3"/>
       <material name="white" />
    </visual>
    <collision>
      <geometry>
        <box size="0.6 0.1 0.2" />
      </geometry>
    </collision>
    <inertial>
      <mass value="1" />
      <inertia ixx="0.030833333" ixy="0" ixz="0"
                iyy="0.030333333" iyz="0"
                izz="0.004166666" />
    </inertial>
  </link>

  <link name="left_leg">
    <visual>
      <geometry>
        <box size="0.6 0.1 0.2" />
      </geometry>
      <origin rpy="0 1.57075 0" xyz="0 0 -0.3" />
      <material name="white" />
    </visual>
    <collision>
      <geometry>
        <box size="0.6 0.1 0.2" />
      </geometry>
    </collision>
    <inertial>
      <mass value="1" />
      <inertia ixx="0.030833333" ixy="0" ixz="0"
                iyy="0.030333333" iyz="0"
                izz="0.004166666" />
    </inertial>
  </link>

  <link name="head">
    <visual>
      <geometry>
        <sphere radius="0.2" />
      </geometry>
      <material name="white" />
    </visual>
    <collision>
      <geometry>
        <cylinder length="0.4" radius="0.2" />
      </geometry>
    </collision>
    <inertial>
      <mass value="1" />
      <inertia ixx="0.046188021" ixy="0" ixz="0"
                iyy="0.046188021" iyz="0"
                izz="0.046188021" />
    </inertial>
  </link>

  <link name="right_wheel_base">
    <visual>
      <geometry>
        <box size="0.4 .1 .1" />
      </geometry>
      <material name="yellow" />
    </visual>
    <collision>
      <geometry>
        <box size="0.4 .1 .1" />
      </geometry>
    </collision>
    <inertial>
      <mass value="3" />
      <inertia ixx="0.001666666" ixy="0" ixz="0"
                iyy="0.014166666" iyz="0"
                izz="0.014166666" />
    </inertial>
  </link>

  <link name="left_wheel_base">
    <visual>
      <geometry>
        <box size="0.4 .1 .1" />
      </geometry>
      <material name="yellow" />
    </visual>
    <collision>
      <geometry>
        <box size="0.4 .1 .1" />
      </geometry>
    </collision>
    <inertial>
      <mass value="3" />
      <inertia ixx="0.001666666" ixy="0" ixz="0"
                iyy="0.014166666" iyz="0"
                izz="0.014166666" />
    </inertial>
  </link>

  <link name="right_front_wheel">
    <visual>
      <geometry>
        <cylinder length="0.1" radius="0.035" />
      </geometry>
      <origin rpy="1.57075 0 0" />
      <material name="black" />
    </visual>
    <collision>
      <geometry>
        <cylinder length="0.1" radius="0.035" />
      </geometry>
    </collision>
    <inertial>
      <mass value="0.1" />
      <inertia ixx="0.00006125" ixy="0" ixz="0"
                iyy="0.001139583" iyz="0"
                izz="0.001139583" />
    </inertial>
  </link>

  <link name="right_back_wheel">
    <visual>
      <geometry>
        <cylinder length="0.1" radius="0.035" />
      </geometry>
      <origin rpy="1.57075 0 0" />
      <material name="black" />
    </visual>
     <collision>
      <geometry>
        <cylinder length="0.1" radius="0.035" />
      </geometry>
    </collision>
    <inertial>
      <mass value="0.1" />
      <inertia ixx="0.00006125" ixy="0" ixz="0"
                iyy="0.001139583" iyz="0"
                izz="0.001139583" />
    </inertial>
  </link>

  <link name="left_back_wheel">
    <visual>
      <geometry>
        <cylinder length="0.1" radius="0.035" />
      </geometry>
      <origin rpy="1.57075 0 0" />
      <material name="black" />
    </visual>
     <collision>
      <geometry>
        <cylinder length="0.1" radius="0.035" />
      </geometry>
    </collision>
    <inertial>
      <mass value="0.1" />
      <inertia ixx="0.00006125" ixy="0" ixz="0"
                iyy="0.001139583" iyz="0"
                izz="0.001139583" />
    </inertial>
  </link>

  <link name="left_front_wheel">
    <visual>
      <geometry>
        <cylinder length="0.1" radius="0.035" />
      </geometry>
      <origin rpy="1.57075 0 0" />
      <material name="black" />
    </visual>
     <collision>
      <geometry>
        <cylinder length="0.1" radius="0.035" />
      </geometry>
    </collision>
    <inertial>
      <mass value="0.1" />
      <inertia ixx="0.00006125" ixy="0" ixz="0"
                iyy="0.001139583" iyz="0"
                izz="0.001139583" />
    </inertial>
  </link>

  <joint name="gripper_extension" type="prismatic">
    <limit effort="1000.0" lower="-0.38" upper="0" velocity="0.5"/>
    <parent link="base_link"/>
    <child link="gripper_pole"/>
    <origin rpy="0 0 0" xyz="0.19 0 0.2"/>
  </joint>

  <link name="gripper_pole">
    <visual>
      <geometry>
        <cylinder length="0.2" radius="0.01"/>
      </geometry>
      <origin rpy="0 1.57075 0 " xyz="0.1 0 0"/>
    </visual>
    <collision>
      <geometry>
        <cylinder length="0.2" radius="0.01"/>
      </geometry>
    </collision>
    <inertial>
      <mass value="0.1" />
      <inertia ixx="0.000335833" ixy="0" ixz="0"
                iyy="0.000005" iyz="0"
                izz="0.000335833" />
    </inertial>
  </link>

  <joint name="left_gripper_joint" type="revolute">
    <axis xyz="0 0 1"/>
    <limit effort="1000.0" lower="0.0" upper="0.548" velocity="0.5"/>
    <origin rpy="0 0 0" xyz="0.2 0.01 0"/>
    <parent link="gripper_pole"/>
    <child link="left_gripper"/>
  </joint>

  <link name="left_gripper">
    <visual>
      <origin rpy="0.0 0 0" xyz="0 0 0"/>
      <geometry>
        <mesh filename="package://urdf_tutorial/meshes/l_finger.dae"/>
      </geometry>
    </visual>
    <collision>
       <geometry>
        <mesh filename="package://urdf_tutorial/meshes/l_finger.dae"/>
      </geometry>
    </collision>
    <inertial>
      <mass value="0.05" />
      <inertia ixx="0.000001" ixy="0" ixz="0"
                iyy="0.000001" iyz="0"
                izz="0.0000001" />
    </inertial>
  </link>

  <joint name="left_tip_joint" type="fixed">
    <parent link="left_gripper"/>
    <child link="left_tip"/>
  </joint>

  <link name="left_tip">
    <visual>
      <origin rpy="0.0 0 0" xyz="0.09137 0.00495 0"/>
      <geometry>
        <mesh filename="package://urdf_tutorial/meshes/l_finger_tip.dae"/>
      </geometry>
    </visual>
    <collision>
      <geometry>
        <mesh filename="package://urdf_tutorial/meshes/l_finger_tip.dae"/>
      </geometry>
    </collision>
    <inertial>
      <mass value="0.05" />
      <inertia ixx="0.0000001" ixy="0" ixz="0"
                iyy="0.0000001" iyz="0"
                izz="0.0000001" />
    </inertial>
  </link>
  <joint name="right_gripper_joint" type="revolute">
    <axis xyz="0 0 1" />
    <limit effort="1000.0" lower="-0.548" upper="0.0" velocity="0.5"/>
    <origin rpy="0 0 0" xyz="0.2 -0.01 0"/>
    <parent link="gripper_pole"/>
    <child link="right_gripper"/>
  </joint>

  <link name="right_gripper">
    <visual>
      <origin rpy="-3.1415 0 0" xyz="0 0 0"/>
      <geometry>
        <mesh filename="package://urdf_tutorial/meshes/l_finger.dae"/>
      </geometry>
    </visual>
    <inertial>
      <mass value="0.05" />
      <inertia ixx="0.0000001" ixy="0" ixz="0"
                iyy="0.0000001" iyz="0"
                izz="0.0000001" />
    </inertial>
    <collision>
      <geometry>
        <mesh filename="package://urdf_tutorial/meshes/l_finger.dae"/>
      </geometry>
    </collision>
  </link>

  <joint name="right_tip_joint" type="fixed">
    <parent link="right_gripper"/>
    <child link="right_tip"/>
  </joint>

  <link name="right_tip">
    <visual>
      <origin rpy="-3.1415 0 0" xyz="0.09137 0.00495 0"/>
      <geometry>
        <mesh filename="package://urdf_tutorial/meshes/l_finger_tip.dae"/>
      </geometry>
      <material name="yellow" />
    </visual>
    <inertial>
      <mass value="0.05" />
      <inertia ixx="0.0000001" ixy="0" ixz="0"
                iyy="0.0000001" iyz="0"
                izz="0.0000001" />
    </inertial>
    <collision>
      <geometry>
        <mesh filename="package://urdf_tutorial/meshes/l_finger_tip.dae"/>
      </geometry>
    </collision>
  </link>

  <link name="box">
    <visual>
      <geometry>
        <box size="0.08 0.08 0.08"/>
      </geometry>
      <material name="blue"/>
    </visual>
    <collision>
      <geometry>
        <box size="0.08 0.08 0.08"/>
      </geometry>
    </collision>
    <inertial>
      <mass value="0.05" />
      <inertia ixx="0.001066666" ixy="0" ixz="0"
                iyy="0.001066666" iyz="0"
                izz="0.001066666" />
    </inertial>
  </link>

  <joint name="tobox" type="fixed">
    <parent link="head"/>
    <child link="box"/>
    <origin xyz="0.1814 0 0.1414"/>
  </joint>

  <joint name="base_to_right_leg" type="fixed">
    <parent link="base_link" />
    <child link="right_leg" />
    <origin xyz="0 -0.22 0.25"/>
  </joint>

  <joint name="base_to_left_leg" type="fixed">
    <parent link="base_link" />
    <child link="left_leg" />
    <origin xyz="0 0.22 0.25" />
  </joint>

  <joint name="base_to_head" type="continuous">
    <parent link="base_link" />
    <child link="head" />
    <origin xyz="0 0 0.3" />
    <axis xyz="0 0 1" />
  </joint>

  <joint name="right_wheel_to_right_leg" type="fixed">
    <parent link="right_leg" />
    <child link="right_wheel_base" />
    <origin xyz="0 0 -0.6" />
  </joint>

  <joint name="left_wheel_to_left_leg" type="fixed">
    <parent link="left_leg" />
    <child link="left_wheel_base" />
    <origin xyz="0 0 -0.6" />
  </joint>

  <joint name="right_front_wheel_to_base" type="continuous">
    <parent link="right_wheel_base" />
    <child link="right_front_wheel" />
    <origin xyz="0.133333333333 0 -0.085" />
    <axis xyz="1 0 0" />
  </joint>

  <joint name="right_back_wheel_to_base" type="continuous">
    <parent link="right_wheel_base" />
    <child link="right_back_wheel" />
    <origin xyz="-0.133333333333 0 -0.085" />
    <axis xyz="1 0 0" />
  </joint>

  <joint name="left_front_wheel_to_base" type="continuous">
    <parent link="left_wheel_base" />
    <child link="left_front_wheel" />
    <origin xyz="0.133333333333 0 -0.085" />
    <axiz xyz="1 0 0" />
  </joint>

  <joint name="left_back_wheel_to_base" type="continuous">
    <parent link="left_wheel_base" />
    <child link="left_back_wheel" />
    <origin xyz="-0.133333333333 0 -0.085" />
    <axiz xyz="1 0 0" />
  </joint>

</robot>